Workbook

Sheet Metrics
A1: Cedar Valley Tech — AEO Reporting Data Layer (SYNTHETIC SAMPLE DATA)
A2: One row per metric, one column per month. Enter values in the month columns only — the Deltas tab calculates every MoM and YTD change automatically.
A3: LEGEND: yellow = you fill this each month · red = backfilled from a prior deck but internally contradictory, verify in Semrush before citing · white = already verified
A5: Metric | B5: Δ Type | C5: Semrush AIO source | D5: Notes / definition | E5: Jan-26 | F5: Feb-26 | G5: Mar-26 | H5: Apr-26 | I5: May-26 | J5: Jun-26 | K5: Jul-26 | L5: Aug-26 | M5: Sep-26 | N5: Oct-26 | O5: Nov-26 | P5: Dec-26
A6: VISIBILITY OVERVIEW (all topics — not tracked prompts)
A7: AI Visibility score | B7: pp | C7: AI Visibility > Visibility Overview | D7: Semrush proprietary 0-100 composite. NOT a percentage. July = 34 on Country=US (the Worldwide pull returned 22 and admitted non-US markets). Mar and May both reported 39. | G7: 39 | I7: 39 | K7: 34
A8: Share of Voice — overall | B8: pp | C8: Prompt Tracking > Overview | D8: Brand's share of all brand mentions in the topic set. | G8: 0.58
A9: Source Visibility — overall | B9: pp | C9: Prompt Tracking > Overview | D9: Share of responses citing a brand URL as a source. | G9: 0.51
A10: Mentions — total (all topics) | B10: pct | C10: AI Visibility > Visibility Overview | D10: Trend on Visibility Overview: ~920 Mar, peak ~980 Apr, ~550 by Jul, flat since. Absolute mentions are down ~40% from the April peak while the composite score fell only 5 points — competitors are falling too. | K10: 612
A11: Monthly Audience | B11: pct | C11: AI Visibility > Visibility Overview | D11: Total search volume of topics where brand is mentioned. | K11: 14200000
A12: Cited Pages | B12: pct | C12: AI Visibility > Visibility Overview | D12: Count of distinct brand URLs referenced in LLM answers. | K12: 388
A13: Negative sentiment (mentions) | B13: pp | C13: Prompt Tracking > Concepts and Sentiment | D13: NEW — shipped in Enterprise AIO 5/7/26. Not in any prior report. Add this month.
A14: reddit.com source visibility | B14: pct | C14: Prompt Tracking > Sources | D14: NEW — shipped in Enterprise AIO 5/7/26. High signal for college-choice queries.
A15: TRACKED PROMPTS (the managed prompt set)
A16: Prompts tracked (count) | B16: abs | C16: Prompt Tracking > Rankings | D16: CONTRADICTION: June+May headline slides say 25; May appendix tables list 68; March says 34. Resolve. | G16: 34 | I16: 25 | J16: 25
A17: Models tracked (count) | B17: abs | C17: Prompt Tracking > Overview > Performance by Model | D17: March: ChatGPT / Google AIO / Perplexity. June: 3 models, composition unconfirmed. | G17: 3 | J17: 3
A18: Share of Voice — tracked | B18: pp | C18: Prompt Tracking > Overview | D18: June deck states +4pp vs May but gives no absolute value. Pull both.
A19: Brand Visibility — tracked | B19: pp | C19: Prompt Tracking > Overview | D19: June deck states +3pp vs May but gives no absolute value. Pull both.
A20: Avg. position — tracked | B20: abs | C20: Prompt Tracking > Rankings | D20: LOWER IS BETTER. Never write 'up' for an improvement here — June deck did. | I20: 1.6 | J20: 1.4
A21: Responses w/ brand mention | B21: pct | C21: Prompt Tracking > Overview > Mentions | D21: June deck states +22% vs May, no absolute. Pull both.
A22: Total mentions | B22: pct | C22: Prompt Tracking > Overview | D22: Flagged in June deck as a new metric to start tracking.
A23: Total responses | B23: pct | C23: Prompt Tracking > Overview | D23: Flagged in June deck as a new metric to start tracking.
A24: TRAFFIC (GA4 / AI Traffic dashboard)
A25: LLM traffic — total visits | B25: pct | C25: GA4 (LLM source segment) | D25: Traffic Analysis > AI Referral Traffic (GA). Semrush has the GA connection built in — no manual GA4 segment needed. July 1,046, +17% vs June. | I25: 701 | J25: 894 | K25: 1046
A26: ChatGPT visits | B26: pct | C26: GA4 (LLM source segment) | D26: Traffic by Model. ChatGPT is 94% of all AI referral traffic; Gemini, Perplexity, Copilot and Claude are rounding errors. | I26: 655 | J26: 842 | K26: 983
A27: All other LLM visits | B27: pct | C27: Calculated | D27: Total minus ChatGPT. Perplexity/Copilot/Claude dropped from traffic tracking as of May. | E27: =IFERROR(IF(OR(E25="",E26=""),"",E25-E26),"") | F27: =IFERROR(IF(OR(F25="",F26=""),"",F25-F26),"") | G27: =IFERROR(IF(OR(G25="",G26=""),"",G25-G26),"") | H27: =IFERROR(IF(OR(H25="",H26=""),"",H25-H26),"") | I27: =IFERROR(IF(OR(I25="",I26=""),"",I25-I26),"") | J27: =IFERROR(IF(OR(J25="",J26=""),"",J25-J26),"") | K27: =IFERROR(IF(OR(K25="",K26=""),"",K25-K26),"") | L27: =IFERROR(IF(OR(L25="",L26=""),"",L25-L26),"") | ... P27: =IFERROR(IF(OR(P25="",P26=""),"",P25-P26),"")
A28: Conversions | B28: pct | C28: GA4 key events — see note | D28: BROKEN METRIC — do not present as applications. On the Landing Page Performance table, /apply/apply-now/ shows 26 AI sessions and 47 AI conversions. More conversions than sessions means the event fires repeatedly per session. Answers the agency contact's 7/22 question. | I28: 31 | J28: 84 | K28: 158
A29: Conversion rate | B29: pp | C29: Calculated | D29: Conversions ÷ total LLM visits. | E29: =IFERROR(E28/E25,"") | F29: =IFERROR(F28/F25,"") | G29: =IFERROR(G28/G25,"") | H29: =IFERROR(H28/H25,"") | I29: =IFERROR(I28/I25,"") | J29: =IFERROR(J28/J25,"") | K29: =IFERROR(K28/K25,"") | L29: =IFERROR(L28/L25,"") | ... P29: =IFERROR(P28/P25,"")
A30: Bounce rate | B30: pp | C30: GA4 (LLM source segment) | D30: July 28%, down 12% vs June. DOWN is good — the June deck grouped a rising bounce rate under 'all metrics pointing up'. | I30: 0.32 | J30: 0.318 | K30: 0.28
A32: Sources: prior Cedar Valley Tech AEO decks Mar/May/Jun '26; Semrush KB 'AI Visibility Features'; Semrush product releases 5/7/26 and 5/14/26.
A34: BY MODEL — Prompt Tracking > Overview > Performance by Model
A35: Gemini — Share of Voice | B35: pp | C35: Prompt Tracking > Overview | D35: July = first month captured at model level. | K35: 0.84
A36: Gemini — Visibility | B36: pp | C36: Prompt Tracking > Overview | D36: July = first month captured at model level. | K36: 0.95
A37: Gemini — Mentions | B37: pct | C37: Prompt Tracking > Overview | D37: July = first month captured at model level. | K37: 738
A38: ChatGPT — Share of Voice | B38: pp | C38: Prompt Tracking > Overview | D38: July = first month captured at model level. | K38: 0.73
A39: ChatGPT — Visibility | B39: pp | C39: Prompt Tracking > Overview | D39: July = first month captured at model level. | K39: 0.83
A40: ChatGPT — Mentions | B40: pct | C40: Prompt Tracking > Overview | D40: July = first month captured at model level. | K40: 652
A41: Google AI Overview — Share of Voice | B41: pp | C41: Prompt Tracking > Overview | D41: July = first month captured at model level. | K41: 0.61
A42: Google AI Overview — Visibility | B42: pp | C42: Prompt Tracking > Overview | D42: July = first month captured at model level. | K42: 0.7
A43: Google AI Overview — Mentions | B43: pct | C43: Prompt Tracking > Overview | D43: July = first month captured at model level. | K43: 478
...

Sheet Deltas
A1: Auto-calculated changes — do not type in this sheet
A2: MoM = change vs. prior month. YTD = change vs. the earliest month with data. 'pp' metrics show percentage-point change; 'pct' metrics show percent change; 'abs' metrics show absolute change.
A3: The agency contact asked for YTD alongside MoM (comment, 7/22/26). That is the YTD column.
A5: Metric | B5: Δ Type | C5: Feb-26 MoM | D5: Mar-26 MoM | E5: Apr-26 MoM | F5: May-26 MoM | G5: Jun-26 MoM | H5: Jul-26 MoM | I5: Aug-26 MoM | J5: Sep-26 MoM | K5: Oct-26 MoM | L5: Nov-26 MoM | M5: Dec-26 MoM | N5: YTD
A6: VISIBILITY OVERVIEW (all topics — not tracked prompts)
A7: AI Visibility score | B7: pp | C7: =IFERROR(IF(OR(Metrics!F7="",Metrics!E7=""),"",Metrics!F7-Metrics!E7),"") | D7: =IFERROR(IF(OR(Metrics!G7="",Metrics!F7=""),"",Metrics!G7-Metrics!F7),"") | E7: =IFERROR(IF(OR(Metrics!H7="",Metrics!G7=""),"",Metrics!H7-Metrics!G7),"") | F7: =IFERROR(IF(OR(Metrics!I7="",Metrics!H7=""),"",Metrics!I7-Metrics!H7),"") | G7: =IFERROR(IF(OR(Metrics!J7="",Metrics!I7=""),"",Metrics!J7-Metrics!I7),"") | H7: =IFERROR(IF(OR(Metrics!K7="",Metrics!J7=""),"",Metrics!K7-Metrics!J7),"") | I7: =IFERROR(IF(OR(Metrics!L7="",Metrics!K7=""),"",Metrics!L7-Metrics!K7),"") | J7: =IFERROR(IF(OR(Metrics!M7="",Metrics!L7=""),"",Metrics!M7-Metrics!L7),"") | ... M7: =IFERROR(IF(OR(Metrics!P7="",Metrics!O7=""),"",Metrics!P7-Metrics!O7),"") | N7: =IFERROR(INDEX(Metrics!$E$7:$P$7,MATCH(9.99E+307,Metrics!$E$7:$P$7))-INDEX(Metrics!$E$7:$P$7,MATCH(TRUE(),INDEX(Metrics!$E$7:$P$7<>"",0),0)),"")
A8: Share of Voice — overall | B8: pp | C8: =IFERROR(IF(OR(Metrics!F8="",Metrics!E8=""),"",Metrics!F8-Metrics!E8),"") | D8: =IFERROR(IF(OR(Metrics!G8="",Metrics!F8=""),"",Metrics!G8-Metrics!F8),"") | E8: =IFERROR(IF(OR(Metrics!H8="",Metrics!G8=""),"",Metrics!H8-Metrics!G8),"") | F8: =IFERROR(IF(OR(Metrics!I8="",Metrics!H8=""),"",Metrics!I8-Metrics!H8),"") | G8: =IFERROR(IF(OR(Metrics!J8="",Metrics!I8=""),"",Metrics!J8-Metrics!I8),"") | H8: =IFERROR(IF(OR(Metrics!K8="",Metrics!J8=""),"",Metrics!K8-Metrics!J8),"") | I8: =IFERROR(IF(OR(Metrics!L8="",Metrics!K8=""),"",Metrics!L8-Metrics!K8),"") | J8: =IFERROR(IF(OR(Metrics!M8="",Metrics!L8=""),"",Metrics!M8-Metrics!L8),"") | ... M8: =IFERROR(IF(OR(Metrics!P8="",Metrics!O8=""),"",Metrics!P8-Metrics!O8),"") | N8: =IFERROR(INDEX(Metrics!$E$8:$P$8,MATCH(9.99E+307,Metrics!$E$8:$P$8))-INDEX(Metrics!$E$8:$P$8,MATCH(TRUE(),INDEX(Metrics!$E$8:$P$8<>"",0),0)),"")
A9: Source Visibility — overall | B9: pp | C9: =IFERROR(IF(OR(Metrics!F9="",Metrics!E9=""),"",Metrics!F9-Metrics!E9),"") | D9: =IFERROR(IF(OR(Metrics!G9="",Metrics!F9=""),"",Metrics!G9-Metrics!F9),"") | E9: =IFERROR(IF(OR(Metrics!H9="",Metrics!G9=""),"",Metrics!H9-Metrics!G9),"") | F9: =IFERROR(IF(OR(Metrics!I9="",Metrics!H9=""),"",Metrics!I9-Metrics!H9),"") | G9: =IFERROR(IF(OR(Metrics!J9="",Metrics!I9=""),"",Metrics!J9-Metrics!I9),"") | H9: =IFERROR(IF(OR(Metrics!K9="",Metrics!J9=""),"",Metrics!K9-Metrics!J9),"") | I9: =IFERROR(IF(OR(Metrics!L9="",Metrics!K9=""),"",Metrics!L9-Metrics!K9),"") | J9: =IFERROR(IF(OR(Metrics!M9="",Metrics!L9=""),"",Metrics!M9-Metrics!L9),"") | ... M9: =IFERROR(IF(OR(Metrics!P9="",Metrics!O9=""),"",Metrics!P9-Metrics!O9),"") | N9: =IFERROR(INDEX(Metrics!$E$9:$P$9,MATCH(9.99E+307,Metrics!$E$9:$P$9))-INDEX(Metrics!$E$9:$P$9,MATCH(TRUE(),INDEX(Metrics!$E$9:$P$9<>"",0),0)),"")
A10: Brand Mentions — total | B10: pct | C10: =IFERROR(IF(OR(Metrics!F10="",Metrics!E10="",Metrics!E10=0),"",Metrics!F10/Metrics!E10-1),"") | D10: =IFERROR(IF(OR(Metrics!G10="",Metrics!F10="",Metrics!F10=0),"",Metrics!G10/Metrics!F10-1),"") | E10: =IFERROR(IF(OR(Metrics!H10="",Metrics!G10="",Metrics!G10=0),"",Metrics!H10/Metrics!G10-1),"") | F10: =IFERROR(IF(OR(Metrics!I10="",Metrics!H10="",Metrics!H10=0),"",Metrics!I10/Metrics!H10-1),"") | G10: =IFERROR(IF(OR(Metrics!J10="",Metrics!I10="",Metrics!I10=0),"",Metrics!J10/Metrics!I10-1),"") | H10: =IFERROR(IF(OR(Metrics!K10="",Metrics!J10="",Metrics!J10=0),"",Metrics!K10/Metrics!J10-1),"") | I10: =IFERROR(IF(OR(Metrics!L10="",Metrics!K10="",Metrics!K10=0),"",Metrics!L10/Metrics!K10-1),"") | J10: =IFERROR(IF(OR(Metrics!M10="",Metrics!L10="",Metrics!L10=0),"",Metrics!M10/Metrics!L10-1),"") | ... M10: =IFERROR(IF(OR(Metrics!P10="",Metrics!O10="",Metrics!O10=0),"",Metrics!P10/Metrics!O10-1),"") | N10: =IFERROR(IF(INDEX(Metrics!$E$10:$P$10,MATCH(TRUE(),INDEX(Metrics!$E$10:$P$10<>"",0),0))=0,"",INDEX(Metrics!$E$10:$P$10,MATCH(9.99E+307,Metrics!$E$10:$P$10))/INDEX(Metrics!$E$10:$P$10,MATCH(TRUE(),INDEX(Metrics!$E$10:$P$10<>"",0),0))-1),"")
A11: Monthly Audience | B11: pct | C11: =IFERROR(IF(OR(Metrics!F11="",Metrics!E11="",Metrics!E11=0),"",Metrics!F11/Metrics!E11-1),"") | D11: =IFERROR(IF(OR(Metrics!G11="",Metrics!F11="",Metrics!F11=0),"",Metrics!G11/Metrics!F11-1),"") | E11: =IFERROR(IF(OR(Metrics!H11="",Metrics!G11="",Metrics!G11=0),"",Metrics!H11/Metrics!G11-1),"") | F11: =IFERROR(IF(OR(Metrics!I11="",Metrics!H11="",Metrics!H11=0),"",Metrics!I11/Metrics!H11-1),"") | G11: =IFERROR(IF(OR(Metrics!J11="",Metrics!I11="",Metrics!I11=0),"",Metrics!J11/Metrics!I11-1),"") | H11: =IFERROR(IF(OR(Metrics!K11="",Metrics!J11="",Metrics!J11=0),"",Metrics!K11/Metrics!J11-1),"") | I11: =IFERROR(IF(OR(Metrics!L11="",Metrics!K11="",Metrics!K11=0),"",Metrics!L11/Metrics!K11-1),"") | J11: =IFERROR(IF(OR(Metrics!M11="",Metrics!L11="",Metrics!L11=0),"",Metrics!M11/Metrics!L11-1),"") | ... M11: =IFERROR(IF(OR(Metrics!P11="",Metrics!O11="",Metrics!O11=0),"",Metrics!P11/Metrics!O11-1),"") | N11: =IFERROR(IF(INDEX(Metrics!$E$11:$P$11,MATCH(TRUE(),INDEX(Metrics!$E$11:$P$11<>"",0),0))=0,"",INDEX(Metrics!$E$11:$P$11,MATCH(9.99E+307,Metrics!$E$11:$P$11))/INDEX(Metrics!$E$11:$P$11,MATCH(TRUE(),INDEX(Metrics!$E$11:$P$11<>"",0),0))-1),"")
A12: Cited Pages | B12: pct | C12: =IFERROR(IF(OR(Metrics!F12="",Metrics!E12="",Metrics!E12=0),"",Metrics!F12/Metrics!E12-1),"") | D12: =IFERROR(IF(OR(Metrics!G12="",Metrics!F12="",Metrics!F12=0),"",Metrics!G12/Metrics!F12-1),"") | E12: =IFERROR(IF(OR(Metrics!H12="",Metrics!G12="",Metrics!G12=0),"",Metrics!H12/Metrics!G12-1),"") | F12: =IFERROR(IF(OR(Metrics!I12="",Metrics!H12="",Metrics!H12=0),"",Metrics!I12/Metrics!H12-1),"") | G12: =IFERROR(IF(OR(Metrics!J12="",Metrics!I12="",Metrics!I12=0),"",Metrics!J12/Metrics!I12-1),"") | H12: =IFERROR(IF(OR(Metrics!K12="",Metrics!J12="",Metrics!J12=0),"",Metrics!K12/Metrics!J12-1),"") | I12: =IFERROR(IF(OR(Metrics!L12="",Metrics!K12="",Metrics!K12=0),"",Metrics!L12/Metrics!K12-1),"") | J12: =IFERROR(IF(OR(Metrics!M12="",Metrics!L12="",Metrics!L12=0),"",Metrics!M12/Metrics!L12-1),"") | ... M12: =IFERROR(IF(OR(Metrics!P12="",Metrics!O12="",Metrics!O12=0),"",Metrics!P12/Metrics!O12-1),"") | N12: =IFERROR(IF(INDEX(Metrics!$E$12:$P$12,MATCH(TRUE(),INDEX(Metrics!$E$12:$P$12<>"",0),0))=0,"",INDEX(Metrics!$E$12:$P$12,MATCH(9.99E+307,Metrics!$E$12:$P$12))/INDEX(Metrics!$E$12:$P$12,MATCH(TRUE(),INDEX(Metrics!$E$12:$P$12<>"",0),0))-1),"")
A13: Negative Sentiment % | B13: pp | C13: =IFERROR(IF(OR(Metrics!F13="",Metrics!E13=""),"",Metrics!F13-Metrics!E13),"") | D13: =IFERROR(IF(OR(Metrics!G13="",Metrics!F13=""),"",Metrics!G13-Metrics!F13),"") | E13: =IFERROR(IF(OR(Metrics!H13="",Metrics!G13=""),"",Metrics!H13-Metrics!G13),"") | F13: =IFERROR(IF(OR(Metrics!I13="",Metrics!H13=""),"",Metrics!I13-Metrics!H13),"") | G13: =IFERROR(IF(OR(Metrics!J13="",Metrics!I13=""),"",Metrics!J13-Metrics!I13),"") | H13: =IFERROR(IF(OR(Metrics!K13="",Metrics!J13=""),"",Metrics!K13-Metrics!J13),"") | I13: =IFERROR(IF(OR(Metrics!L13="",Metrics!K13=""),"",Metrics!L13-Metrics!K13),"") | J13: =IFERROR(IF(OR(Metrics!M13="",Metrics!L13=""),"",Metrics!M13-Metrics!L13),"") | ... M13: =IFERROR(IF(OR(Metrics!P13="",Metrics!O13=""),"",Metrics!P13-Metrics!O13),"") | N13: =IFERROR(INDEX(Metrics!$E$13:$P$13,MATCH(9.99E+307,Metrics!$E$13:$P$13))-INDEX(Metrics!$E$13:$P$13,MATCH(TRUE(),INDEX(Metrics!$E$13:$P$13<>"",0),0)),"")
A14: Reddit citations | B14: pct | C14: =IFERROR(IF(OR(Metrics!F14="",Metrics!E14="",Metrics!E14=0),"",Metrics!F14/Metrics!E14-1),"") | D14: =IFERROR(IF(OR(Metrics!G14="",Metrics!F14="",Metrics!F14=0),"",Metrics!G14/Metrics!F14-1),"") | E14: =IFERROR(IF(OR(Metrics!H14="",Metrics!G14="",Metrics!G14=0),"",Metrics!H14/Metrics!G14-1),"") | F14: =IFERROR(IF(OR(Metrics!I14="",Metrics!H14="",Metrics!H14=0),"",Metrics!I14/Metrics!H14-1),"") | G14: =IFERROR(IF(OR(Metrics!J14="",Metrics!I14="",Metrics!I14=0),"",Metrics!J14/Metrics!I14-1),"") | H14: =IFERROR(IF(OR(Metrics!K14="",Metrics!J14="",Metrics!J14=0),"",Metrics!K14/Metrics!J14-1),"") | I14: =IFERROR(IF(OR(Metrics!L14="",Metrics!K14="",Metrics!K14=0),"",Metrics!L14/Metrics!K14-1),"") | J14: =IFERROR(IF(OR(Metrics!M14="",Metrics!L14="",Metrics!L14=0),"",Metrics!M14/Metrics!L14-1),"") | ... M14: =IFERROR(IF(OR(Metrics!P14="",Metrics!O14="",Metrics!O14=0),"",Metrics!P14/Metrics!O14-1),"") | N14: =IFERROR(IF(INDEX(Metrics!$E$14:$P$14,MATCH(TRUE(),INDEX(Metrics!$E$14:$P$14<>"",0),0))=0,"",INDEX(Metrics!$E$14:$P$14,MATCH(9.99E+307,Metrics!$E$14:$P$14))/INDEX(Metrics!$E$14:$P$14,MATCH(TRUE(),INDEX(Metrics!$E$14:$P$14<>"",0),0))-1),"")
A15: TRACKED PROMPTS (the managed prompt set)
A16: Prompts tracked (count) | B16: abs | C16: =IFERROR(IF(OR(Metrics!F16="",Metrics!E16=""),"",Metrics!F16-Metrics!E16),"") | D16: =IFERROR(IF(OR(Metrics!G16="",Metrics!F16=""),"",Metrics!G16-Metrics!F16),"") | E16: =IFERROR(IF(OR(Metrics!H16="",Metrics!G16=""),"",Metrics!H16-Metrics!G16),"") | F16: =IFERROR(IF(OR(Metrics!I16="",Metrics!H16=""),"",Metrics!I16-Metrics!H16),"") | G16: =IFERROR(IF(OR(Metrics!J16="",Metrics!I16=""),"",Metrics!J16-Metrics!I16),"") | H16: =IFERROR(IF(OR(Metrics!K16="",Metrics!J16=""),"",Metrics!K16-Metrics!J16),"") | I16: =IFERROR(IF(OR(Metrics!L16="",Metrics!K16=""),"",Metrics!L16-Metrics!K16),"") | J16: =IFERROR(IF(OR(Metrics!M16="",Metrics!L16=""),"",Metrics!M16-Metrics!L16),"") | ... M16: =IFERROR(IF(OR(Metrics!P16="",Metrics!O16=""),"",Metrics!P16-Metrics!O16),"") | N16: =IFERROR(INDEX(Metrics!$E$16:$P$16,MATCH(9.99E+307,Metrics!$E$16:$P$16))-INDEX(Metrics!$E$16:$P$16,MATCH(TRUE(),INDEX(Metrics!$E$16:$P$16<>"",0),0)),"")
A17: Models tracked (count) | B17: abs | C17: =IFERROR(IF(OR(Metrics!F17="",Metrics!E17=""),"",Metrics!F17-Metrics!E17),"") | D17: =IFERROR(IF(OR(Metrics!G17="",Metrics!F17=""),"",Metrics!G17-Metrics!F17),"") | E17: =IFERROR(IF(OR(Metrics!H17="",Metrics!G17=""),"",Metrics!H17-Metrics!G17),"") | F17: =IFERROR(IF(OR(Metrics!I17="",Metrics!H17=""),"",Metrics!I17-Metrics!H17),"") | G17: =IFERROR(IF(OR(Metrics!J17="",Metrics!I17=""),"",Metrics!J17-Metrics!I17),"") | H17: =IFERROR(IF(OR(Metrics!K17="",Metrics!J17=""),"",Metrics!K17-Metrics!J17),"") | I17: =IFERROR(IF(OR(Metrics!L17="",Metrics!K17=""),"",Metrics!L17-Metrics!K17),"") | J17: =IFERROR(IF(OR(Metrics!M17="",Metrics!L17=""),"",Metrics!M17-Metrics!L17),"") | ... M17: =IFERROR(IF(OR(Metrics!P17="",Metrics!O17=""),"",Metrics!P17-Metrics!O17),"") | N17: =IFERROR(INDEX(Metrics!$E$17:$P$17,MATCH(9.99E+307,Metrics!$E$17:$P$17))-INDEX(Metrics!$E$17:$P$17,MATCH(TRUE(),INDEX(Metrics!$E$17:$P$17<>"",0),0)),"")
A18: Share of Voice — tracked | B18: pp | C18: =IFERROR(IF(OR(Metrics!F18="",Metrics!E18=""),"",Metrics!F18-Metrics!E18),"") | D18: =IFERROR(IF(OR(Metrics!G18="",Metrics!F18=""),"",Metrics!G18-Metrics!F18),"") | E18: =IFERROR(IF(OR(Metrics!H18="",Metrics!G18=""),"",Metrics!H18-Metrics!G18),"") | F18: =IFERROR(IF(OR(Metrics!I18="",Metrics!H18=""),"",Metrics!I18-Metrics!H18),"") | G18: =IFERROR(IF(OR(Metrics!J18="",Metrics!I18=""),"",Metrics!J18-Metrics!I18),"") | H18: =IFERROR(IF(OR(Metrics!K18="",Metrics!J18=""),"",Metrics!K18-Metrics!J18),"") | I18: =IFERROR(IF(OR(Metrics!L18="",Metrics!K18=""),"",Metrics!L18-Metrics!K18),"") | J18: =IFERROR(IF(OR(Metrics!M18="",Metrics!L18=""),"",Metrics!M18-Metrics!L18),"") | ... M18: =IFERROR(IF(OR(Metrics!P18="",Metrics!O18=""),"",Metrics!P18-Metrics!O18),"") | N18: =IFERROR(INDEX(Metrics!$E$18:$P$18,MATCH(9.99E+307,Metrics!$E$18:$P$18))-INDEX(Metrics!$E$18:$P$18,MATCH(TRUE(),INDEX(Metrics!$E$18:$P$18<>"",0),0)),"")
A19: Brand Visibility — tracked | B19: pp | C19: =IFERROR(IF(OR(Metrics!F19="",Metrics!E19=""),"",Metrics!F19-Metrics!E19),"") | D19: =IFERROR(IF(OR(Metrics!G19="",Metrics!F19=""),"",Metrics!G19-Metrics!F19),"") | E19: =IFERROR(IF(OR(Metrics!H19="",Metrics!G19=""),"",Metrics!H19-Metrics!G19),"") | F19: =IFERROR(IF(OR(Metrics!I19="",Metrics!H19=""),"",Metrics!I19-Metrics!H19),"") | G19: =IFERROR(IF(OR(Metrics!J19="",Metrics!I19=""),"",Metrics!J19-Metrics!I19),"") | H19: =IFERROR(IF(OR(Metrics!K19="",Metrics!J19=""),"",Metrics!K19-Metrics!J19),"") | I19: =IFERROR(IF(OR(Metrics!L19="",Metrics!K19=""),"",Metrics!L19-Metrics!K19),"") | J19: =IFERROR(IF(OR(Metrics!M19="",Metrics!L19=""),"",Metrics!M19-Metrics!L19),"") | ... M19: =IFERROR(IF(OR(Metrics!P19="",Metrics!O19=""),"",Metrics!P19-Metrics!O19),"") | N19: =IFERROR(INDEX(Metrics!$E$19:$P$19,MATCH(9.99E+307,Metrics!$E$19:$P$19))-INDEX(Metrics!$E$19:$P$19,MATCH(TRUE(),INDEX(Metrics!$E$19:$P$19<>"",0),0)),"")
A20: Avg. position — tracked | B20: abs | C20: =IFERROR(IF(OR(Metrics!F20="",Metrics!E20=""),"",Metrics!F20-Metrics!E20),"") | D20: =IFERROR(IF(OR(Metrics!G20="",Metrics!F20=""),"",Metrics!G20-Metrics!F20),"") | E20: =IFERROR(IF(OR(Metrics!H20="",Metrics!G20=""),"",Metrics!H20-Metrics!G20),"") | F20: =IFERROR(IF(OR(Metrics!I20="",Metrics!H20=""),"",Metrics!I20-Metrics!H20),"") | G20: =IFERROR(IF(OR(Metrics!J20="",Metrics!I20=""),"",Metrics!J20-Metrics!I20),"") | H20: =IFERROR(IF(OR(Metrics!K20="",Metrics!J20=""),"",Metrics!K20-Metrics!J20),"") | I20: =IFERROR(IF(OR(Metrics!L20="",Metrics!K20=""),"",Metrics!L20-Metrics!K20),"") | J20: =IFERROR(IF(OR(Metrics!M20="",Metrics!L20=""),"",Metrics!M20-Metrics!L20),"") | ... M20: =IFERROR(IF(OR(Metrics!P20="",Metrics!O20=""),"",Metrics!P20-Metrics!O20),"") | N20: =IFERROR(INDEX(Metrics!$E$20:$P$20,MATCH(9.99E+307,Metrics!$E$20:$P$20))-INDEX(Metrics!$E$20:$P$20,MATCH(TRUE(),INDEX(Metrics!$E$20:$P$20<>"",0),0)),"")
A21: Responses w/ brand mention | B21: pct | C21: =IFERROR(IF(OR(Metrics!F21="",Metrics!E21="",Metrics!E21=0),"",Metrics!F21/Metrics!E21-1),"") | D21: =IFERROR(IF(OR(Metrics!G21="",Metrics!F21="",Metrics!F21=0),"",Metrics!G21/Metrics!F21-1),"") | E21: =IFERROR(IF(OR(Metrics!H21="",Metrics!G21="",Metrics!G21=0),"",Metrics!H21/Metrics!G21-1),"") | F21: =IFERROR(IF(OR(Metrics!I21="",Metrics!H21="",Metrics!H21=0),"",Metrics!I21/Metrics!H21-1),"") | G21: =IFERROR(IF(OR(Metrics!J21="",Metrics!I21="",Metrics!I21=0),"",Metrics!J21/Metrics!I21-1),"") | H21: =IFERROR(IF(OR(Metrics!K21="",Metrics!J21="",Metrics!J21=0),"",Metrics!K21/Metrics!J21-1),"") | I21: =IFERROR(IF(OR(Metrics!L21="",Metrics!K21="",Metrics!K21=0),"",Metrics!L21/Metrics!K21-1),"") | J21: =IFERROR(IF(OR(Metrics!M21="",Metrics!L21="",Metrics!L21=0),"",Metrics!M21/Metrics!L21-1),"") | ... M21: =IFERROR(IF(OR(Metrics!P21="",Metrics!O21="",Metrics!O21=0),"",Metrics!P21/Metrics!O21-1),"") | N21: =IFERROR(IF(INDEX(Metrics!$E$21:$P$21,MATCH(TRUE(),INDEX(Metrics!$E$21:$P$21<>"",0),0))=0,"",INDEX(Metrics!$E$21:$P$21,MATCH(9.99E+307,Metrics!$E$21:$P$21))/INDEX(Metrics!$E$21:$P$21,MATCH(TRUE(),INDEX(Metrics!$E$21:$P$21<>"",0),0))-1),"")
A22: Total mentions | B22: pct | C22: =IFERROR(IF(OR(Metrics!F22="",Metrics!E22="",Metrics!E22=0),"",Metrics!F22/Metrics!E22-1),"") | D22: =IFERROR(IF(OR(Metrics!G22="",Metrics!F22="",Metrics!F22=0),"",Metrics!G22/Metrics!F22-1),"") | E22: =IFERROR(IF(OR(Metrics!H22="",Metrics!G22="",Metrics!G22=0),"",Metrics!H22/Metrics!G22-1),"") | F22: =IFERROR(IF(OR(Metrics!I22="",Metrics!H22="",Metrics!H22=0),"",Metrics!I22/Metrics!H22-1),"") | G22: =IFERROR(IF(OR(Metrics!J22="",Metrics!I22="",Metrics!I22=0),"",Metrics!J22/Metrics!I22-1),"") | H22: =IFERROR(IF(OR(Metrics!K22="",Metrics!J22="",Metrics!J22=0),"",Metrics!K22/Metrics!J22-1),"") | I22: =IFERROR(IF(OR(Metrics!L22="",Metrics!K22="",Metrics!K22=0),"",Metrics!L22/Metrics!K22-1),"") | J22: =IFERROR(IF(OR(Metrics!M22="",Metrics!L22="",Metrics!L22=0),"",Metrics!M22/Metrics!L22-1),"") | ... M22: =IFERROR(IF(OR(Metrics!P22="",Metrics!O22="",Metrics!O22=0),"",Metrics!P22/Metrics!O22-1),"") | N22: =IFERROR(IF(INDEX(Metrics!$E$22:$P$22,MATCH(TRUE(),INDEX(Metrics!$E$22:$P$22<>"",0),0))=0,"",INDEX(Metrics!$E$22:$P$22,MATCH(9.99E+307,Metrics!$E$22:$P$22))/INDEX(Metrics!$E$22:$P$22,MATCH(TRUE(),INDEX(Metrics!$E$22:$P$22<>"",0),0))-1),"")
A23: Total responses | B23: pct | C23: =IFERROR(IF(OR(Metrics!F23="",Metrics!E23="",Metrics!E23=0),"",Metrics!F23/Metrics!E23-1),"") | D23: =IFERROR(IF(OR(Metrics!G23="",Metrics!F23="",Metrics!F23=0),"",Metrics!G23/Metrics!F23-1),"") | E23: =IFERROR(IF(OR(Metrics!H23="",Metrics!G23="",Metrics!G23=0),"",Metrics!H23/Metrics!G23-1),"") | F23: =IFERROR(IF(OR(Metrics!I23="",Metrics!H23="",Metrics!H23=0),"",Metrics!I23/Metrics!H23-1),"") | G23: =IFERROR(IF(OR(Metrics!J23="",Metrics!I23="",Metrics!I23=0),"",Metrics!J23/Metrics!I23-1),"") | H23: =IFERROR(IF(OR(Metrics!K23="",Metrics!J23="",Metrics!J23=0),"",Metrics!K23/Metrics!J23-1),"") | I23: =IFERROR(IF(OR(Metrics!L23="",Metrics!K23="",Metrics!K23=0),"",Metrics!L23/Metrics!K23-1),"") | J23: =IFERROR(IF(OR(Metrics!M23="",Metrics!L23="",Metrics!L23=0),"",Metrics!M23/Metrics!L23-1),"") | ... M23: =IFERROR(IF(OR(Metrics!P23="",Metrics!O23="",Metrics!O23=0),"",Metrics!P23/Metrics!O23-1),"") | N23: =IFERROR(IF(INDEX(Metrics!$E$23:$P$23,MATCH(TRUE(),INDEX(Metrics!$E$23:$P$23<>"",0),0))=0,"",INDEX(Metrics!$E$23:$P$23,MATCH(9.99E+307,Metrics!$E$23:$P$23))/INDEX(Metrics!$E$23:$P$23,MATCH(TRUE(),INDEX(Metrics!$E$23:$P$23<>"",0),0))-1),"")
A24: TRAFFIC (GA4 / AI Traffic dashboard)
A25: LLM traffic — total visits | B25: pct | C25: =IFERROR(IF(OR(Metrics!F25="",Metrics!E25="",Metrics!E25=0),"",Metrics!F25/Metrics!E25-1),"") | D25: =IFERROR(IF(OR(Metrics!G25="",Metrics!F25="",Metrics!F25=0),"",Metrics!G25/Metrics!F25-1),"") | E25: =IFERROR(IF(OR(Metrics!H25="",Metrics!G25="",Metrics!G25=0),"",Metrics!H25/Metrics!G25-1),"") | F25: =IFERROR(IF(OR(Metrics!I25="",Metrics!H25="",Metrics!H25=0),"",Metrics!I25/Metrics!H25-1),"") | G25: =IFERROR(IF(OR(Metrics!J25="",Metrics!I25="",Metrics!I25=0),"",Metrics!J25/Metrics!I25-1),"") | H25: =IFERROR(IF(OR(Metrics!K25="",Metrics!J25="",Metrics!J25=0),"",Metrics!K25/Metrics!J25-1),"") | I25: =IFERROR(IF(OR(Metrics!L25="",Metrics!K25="",Metrics!K25=0),"",Metrics!L25/Metrics!K25-1),"") | J25: =IFERROR(IF(OR(Metrics!M25="",Metrics!L25="",Metrics!L25=0),"",Metrics!M25/Metrics!L25-1),"") | ... M25: =IFERROR(IF(OR(Metrics!P25="",Metrics!O25="",Metrics!O25=0),"",Metrics!P25/Metrics!O25-1),"") | N25: =IFERROR(IF(INDEX(Metrics!$E$25:$P$25,MATCH(TRUE(),INDEX(Metrics!$E$25:$P$25<>"",0),0))=0,"",INDEX(Metrics!$E$25:$P$25,MATCH(9.99E+307,Metrics!$E$25:$P$25))/INDEX(Metrics!$E$25:$P$25,MATCH(TRUE(),INDEX(Metrics!$E$25:$P$25<>"",0),0))-1),"")
A26: ChatGPT visits | B26: pct | C26: =IFERROR(IF(OR(Metrics!F26="",Metrics!E26="",Metrics!E26=0),"",Metrics!F26/Metrics!E26-1),"") | D26: =IFERROR(IF(OR(Metrics!G26="",Metrics!F26="",Metrics!F26=0),"",Metrics!G26/Metrics!F26-1),"") | E26: =IFERROR(IF(OR(Metrics!H26="",Metrics!G26="",Metrics!G26=0),"",Metrics!H26/Metrics!G26-1),"") | F26: =IFERROR(IF(OR(Metrics!I26="",Metrics!H26="",Metrics!H26=0),"",Metrics!I26/Metrics!H26-1),"") | G26: =IFERROR(IF(OR(Metrics!J26="",Metrics!I26="",Metrics!I26=0),"",Metrics!J26/Metrics!I26-1),"") | H26: =IFERROR(IF(OR(Metrics!K26="",Metrics!J26="",Metrics!J26=0),"",Metrics!K26/Metrics!J26-1),"") | I26: =IFERROR(IF(OR(Metrics!L26="",Metrics!K26="",Metrics!K26=0),"",Metrics!L26/Metrics!K26-1),"") | J26: =IFERROR(IF(OR(Metrics!M26="",Metrics!L26="",Metrics!L26=0),"",Metrics!M26/Metrics!L26-1),"") | ... M26: =IFERROR(IF(OR(Metrics!P26="",Metrics!O26="",Metrics!O26=0),"",Metrics!P26/Metrics!O26-1),"") | N26: =IFERROR(IF(INDEX(Metrics!$E$26:$P$26,MATCH(TRUE(),INDEX(Metrics!$E$26:$P$26<>"",0),0))=0,"",INDEX(Metrics!$E$26:$P$26,MATCH(9.99E+307,Metrics!$E$26:$P$26))/INDEX(Metrics!$E$26:$P$26,MATCH(TRUE(),INDEX(Metrics!$E$26:$P$26<>"",0),0))-1),"")
A27: All other LLM visits | B27: pct | C27: =IFERROR(IF(OR(Metrics!F27="",Metrics!E27="",Metrics!E27=0),"",Metrics!F27/Metrics!E27-1),"") | D27: =IFERROR(IF(OR(Metrics!G27="",Metrics!F27="",Metrics!F27=0),"",Metrics!G27/Metrics!F27-1),"") | E27: =IFERROR(IF(OR(Metrics!H27="",Metrics!G27="",Metrics!G27=0),"",Metrics!H27/Metrics!G27-1),"") | F27: =IFERROR(IF(OR(Metrics!I27="",Metrics!H27="",Metrics!H27=0),"",Metrics!I27/Metrics!H27-1),"") | G27: =IFERROR(IF(OR(Metrics!J27="",Metrics!I27="",Metrics!I27=0),"",Metrics!J27/Metrics!I27-1),"") | H27: =IFERROR(IF(OR(Metrics!K27="",Metrics!J27="",Metrics!J27=0),"",Metrics!K27/Metrics!J27-1),"") | I27: =IFERROR(IF(OR(Metrics!L27="",Metrics!K27="",Metrics!K27=0),"",Metrics!L27/Metrics!K27-1),"") | J27: =IFERROR(IF(OR(Metrics!M27="",Metrics!L27="",Metrics!L27=0),"",Metrics!M27/Metrics!L27-1),"") | ... M27: =IFERROR(IF(OR(Metrics!P27="",Metrics!O27="",Metrics!O27=0),"",Metrics!P27/Metrics!O27-1),"") | N27: =IFERROR(IF(INDEX(Metrics!$E$27:$P$27,MATCH(TRUE(),INDEX(Metrics!$E$27:$P$27<>"",0),0))=0,"",INDEX(Metrics!$E$27:$P$27,MATCH(9.99E+307,Metrics!$E$27:$P$27))/INDEX(Metrics!$E$27:$P$27,MATCH(TRUE(),INDEX(Metrics!$E$27:$P$27<>"",0),0))-1),"")
A28: Conversions | B28: pct | C28: =IFERROR(IF(OR(Metrics!F28="",Metrics!E28="",Metrics!E28=0),"",Metrics!F28/Metrics!E28-1),"") | D28: =IFERROR(IF(OR(Metrics!G28="",Metrics!F28="",Metrics!F28=0),"",Metrics!G28/Metrics!F28-1),"") | E28: =IFERROR(IF(OR(Metrics!H28="",Metrics!G28="",Metrics!G28=0),"",Metrics!H28/Metrics!G28-1),"") | F28: =IFERROR(IF(OR(Metrics!I28="",Metrics!H28="",Metrics!H28=0),"",Metrics!I28/Metrics!H28-1),"") | G28: =IFERROR(IF(OR(Metrics!J28="",Metrics!I28="",Metrics!I28=0),"",Metrics!J28/Metrics!I28-1),"") | H28: =IFERROR(IF(OR(Metrics!K28="",Metrics!J28="",Metrics!J28=0),"",Metrics!K28/Metrics!J28-1),"") | I28: =IFERROR(IF(OR(Metrics!L28="",Metrics!K28="",Metrics!K28=0),"",Metrics!L28/Metrics!K28-1),"") | J28: =IFERROR(IF(OR(Metrics!M28="",Metrics!L28="",Metrics!L28=0),"",Metrics!M28/Metrics!L28-1),"") | ... M28: =IFERROR(IF(OR(Metrics!P28="",Metrics!O28="",Metrics!O28=0),"",Metrics!P28/Metrics!O28-1),"") | N28: =IFERROR(IF(INDEX(Metrics!$E$28:$P$28,MATCH(TRUE(),INDEX(Metrics!$E$28:$P$28<>"",0),0))=0,"",INDEX(Metrics!$E$28:$P$28,MATCH(9.99E+307,Metrics!$E$28:$P$28))/INDEX(Metrics!$E$28:$P$28,MATCH(TRUE(),INDEX(Metrics!$E$28:$P$28<>"",0),0))-1),"")
A29: Conversion rate | B29: pp | C29: =IFERROR(IF(OR(Metrics!F29="",Metrics!E29=""),"",Metrics!F29-Metrics!E29),"") | D29: =IFERROR(IF(OR(Metrics!G29="",Metrics!F29=""),"",Metrics!G29-Metrics!F29),"") | E29: =IFERROR(IF(OR(Metrics!H29="",Metrics!G29=""),"",Metrics!H29-Metrics!G29),"") | F29: =IFERROR(IF(OR(Metrics!I29="",Metrics!H29=""),"",Metrics!I29-Metrics!H29),"") | G29: =IFERROR(IF(OR(Metrics!J29="",Metrics!I29=""),"",Metrics!J29-Metrics!I29),"") | H29: =IFERROR(IF(OR(Metrics!K29="",Metrics!J29=""),"",Metrics!K29-Metrics!J29),"") | I29: =IFERROR(IF(OR(Metrics!L29="",Metrics!K29=""),"",Metrics!L29-Metrics!K29),"") | J29: =IFERROR(IF(OR(Metrics!M29="",Metrics!L29=""),"",Metrics!M29-Metrics!L29),"") | ... M29: =IFERROR(IF(OR(Metrics!P29="",Metrics!O29=""),"",Metrics!P29-Metrics!O29),"") | N29: =IFERROR(INDEX(Metrics!$E$29:$P$29,MATCH(9.99E+307,Metrics!$E$29:$P$29))-INDEX(Metrics!$E$29:$P$29,MATCH(TRUE(),INDEX(Metrics!$E$29:$P$29<>"",0),0)),"")
A30: Bounce rate | B30: pp | C30: =IFERROR(IF(OR(Metrics!F30="",Metrics!E30=""),"",Metrics!F30-Metrics!E30),"") | D30: =IFERROR(IF(OR(Metrics!G30="",Metrics!F30=""),"",Metrics!G30-Metrics!F30),"") | E30: =IFERROR(IF(OR(Metrics!H30="",Metrics!G30=""),"",Metrics!H30-Metrics!G30),"") | F30: =IFERROR(IF(OR(Metrics!I30="",Metrics!H30=""),"",Metrics!I30-Metrics!H30),"") | G30: =IFERROR(IF(OR(Metrics!J30="",Metrics!I30=""),"",Metrics!J30-Metrics!I30),"") | H30: =IFERROR(IF(OR(Metrics!K30="",Metrics!J30=""),"",Metrics!K30-Metrics!J30),"") | I30: =IFERROR(IF(OR(Metrics!L30="",Metrics!K30=""),"",Metrics!L30-Metrics!K30),"") | J30: =IFERROR(IF(OR(Metrics!M30="",Metrics!L30=""),"",Metrics!M30-Metrics!L30),"") | ... M30: =IFERROR(IF(OR(Metrics!P30="",Metrics!O30=""),"",Metrics!P30-Metrics!O30),"") | N30: =IFERROR(INDEX(Metrics!$E$30:$P$30,MATCH(9.99E+307,Metrics!$E$30:$P$30))-INDEX(Metrics!$E$30:$P$30,MATCH(TRUE(),INDEX(Metrics!$E$30:$P$30<>"",0),0)),"")

Sheet Prompt Tracking
A1: Tracked prompts — 25 prompts × 3 models = 75 rows
A2: Two metrics per month. Avg. Position = how high you rank WHEN you appear. Days with Mention = HOW OFTEN. Position alone lies: a prompt that stops appearing on its bad days posts a fake position gain.
A3: Current month → | B3: Jul-26 | C3: Days-with-mention summed across all 75 rows = the 'Responses with mentions' card in the UI.
D4: Jun-26 | F4: Jul-26 | H4: Aug-26 | J4: Sep-26 | L4: Oct-26 | N4: Nov-26 | P4: Dec-26
A5: Prompt | B5: Theme | C5: Model | D5: Pos | E5: Days | F5: Pos | G5: Days | H5: Pos | I5: Days | J5: Pos | K5: Days | L5: Pos | M5: Days | N5: Pos | O5: Days | P5: Pos | Q5: Days | R5: Δ Pos | S5: Δ Days | T5: Verdict
A6: What are affordable college options in Cedar Valley? | B6: Location — affordability | C6: ChatGPT | D6: 1 | E6: 31 | F6: 1.03 | G6: 31 | R6: =IFERROR(IF(AND(ISNUMBER(INDEX($D6:$Q6,MATCH($B$3,$D$4:$Q$4,0))),ISNUMBER(INDEX($D6:$Q6,MATCH($B$3,$D$4:$Q$4,0)-2))),INDEX($D6:$Q6,MATCH($B$3,$D$4:$Q$4,0))-INDEX($D6:$Q6,MATCH($B$3,$D$4:$Q$4,0)-2),""),"") | S6: =IFERROR(IF(AND(ISNUMBER(INDEX($D6:$Q6,MATCH($B$3,$D$4:$Q$4,0)+1)),ISNUMBER(INDEX($D6:$Q6,MATCH($B$3,$D$4:$Q$4,0)-1))),INDEX($D6:$Q6,MATCH($B$3,$D$4:$Q$4,0)+1)-INDEX($D6:$Q6,MATCH($B$3,$D$4:$Q$4,0)-1),""),"") | T6: =IFERROR(IF(S6="","",IF(AND(INDEX($D6:$Q6,MATCH($B$3,$D$4:$Q$4,0)+1)=0,INDEX($D6:$Q6,MATCH($B$3,$D$4:$Q$4,0)-1)>0),"WENT TO ZERO",IF(AND(INDEX($D6:$Q6,MATCH($B$3,$D$4:$Q$4,0)-1)=0,INDEX($D6:$Q6,MATCH($B$3,$D$4:$Q$4,0)+1)>0),"NEW ENTRY",IF(INDEX($D6:$Q6,MATCH($B$3,$D$4:$Q$4,0)-1)=0,"absent",IF(S6/INDEX($D6:$Q6,MATCH($B$3,$D$4:$Q$4,0)-1)<-0.2,"FREQUENCY LOSS",IF(AND(R6<-0.1,S6>=0),"WIN",IF(R6>0.1,"LOSS",IF(S6/INDEX($D6:$Q6,MATCH($B$3,$D$4:$Q$4,0)-1)>0.2,"FREQUENCY GAIN","hold")))))))),"")
A7: What are affordable college options in Cedar Valley? | B7: Location — affordability | C7: Gemini | D7: 1.05 | E7: 31 | F7: 1.01 | G7: 31 | R7: =IFERROR(IF(AND(ISNUMBER(INDEX($D7:$Q7,MATCH($B$3,$D$4:$Q$4,0))),ISNUMBER(INDEX($D7:$Q7,MATCH($B$3,$D$4:$Q$4,0)-2))),INDEX($D7:$Q7,MATCH($B$3,$D$4:$Q$4,0))-INDEX($D7:$Q7,MATCH($B$3,$D$4:$Q$4,0)-2),""),"") | S7: =IFERROR(IF(AND(ISNUMBER(INDEX($D7:$Q7,MATCH($B$3,$D$4:$Q$4,0)+1)),ISNUMBER(INDEX($D7:$Q7,MATCH($B$3,$D$4:$Q$4,0)-1))),INDEX($D7:$Q7,MATCH($B$3,$D$4:$Q$4,0)+1)-INDEX($D7:$Q7,MATCH($B$3,$D$4:$Q$4,0)-1),""),"") | T7: =IFERROR(IF(S7="","",IF(AND(INDEX($D7:$Q7,MATCH($B$3,$D$4:$Q$4,0)+1)=0,INDEX($D7:$Q7,MATCH($B$3,$D$4:$Q$4,0)-1)>0),"WENT TO ZERO",IF(AND(INDEX($D7:$Q7,MATCH($B$3,$D$4:$Q$4,0)-1)=0,INDEX($D7:$Q7,MATCH($B$3,$D$4:$Q$4,0)+1)>0),"NEW ENTRY",IF(INDEX($D7:$Q7,MATCH($B$3,$D$4:$Q$4,0)-1)=0,"absent",IF(S7/INDEX($D7:$Q7,MATCH($B$3,$D$4:$Q$4,0)-1)<-0.2,"FREQUENCY LOSS",IF(AND(R7<-0.1,S7>=0),"WIN",IF(R7>0.1,"LOSS",IF(S7/INDEX($D7:$Q7,MATCH($B$3,$D$4:$Q$4,0)-1)>0.2,"FREQUENCY GAIN","hold")))))))),"")
A8: What are affordable college options in Cedar Valley? | B8: Location — affordability | C8: Google AI Overview | D8: 1.02 | E8: 30 | F8: 1.11 | G8: 25 | R8: =IFERROR(IF(AND(ISNUMBER(INDEX($D8:$Q8,MATCH($B$3,$D$4:$Q$4,0))),ISNUMBER(INDEX($D8:$Q8,MATCH($B$3,$D$4:$Q$4,0)-2))),INDEX($D8:$Q8,MATCH($B$3,$D$4:$Q$4,0))-INDEX($D8:$Q8,MATCH($B$3,$D$4:$Q$4,0)-2),""),"") | S8: =IFERROR(IF(AND(ISNUMBER(INDEX($D8:$Q8,MATCH($B$3,$D$4:$Q$4,0)+1)),ISNUMBER(INDEX($D8:$Q8,MATCH($B$3,$D$4:$Q$4,0)-1))),INDEX($D8:$Q8,MATCH($B$3,$D$4:$Q$4,0)+1)-INDEX($D8:$Q8,MATCH($B$3,$D$4:$Q$4,0)-1),""),"") | T8: =IFERROR(IF(S8="","",IF(AND(INDEX($D8:$Q8,MATCH($B$3,$D$4:$Q$4,0)+1)=0,INDEX($D8:$Q8,MATCH($B$3,$D$4:$Q$4,0)-1)>0),"WENT TO ZERO",IF(AND(INDEX($D8:$Q8,MATCH($B$3,$D$4:$Q$4,0)-1)=0,INDEX($D8:$Q8,MATCH($B$3,$D$4:$Q$4,0)+1)>0),"NEW ENTRY",IF(INDEX($D8:$Q8,MATCH($B$3,$D$4:$Q$4,0)-1)=0,"absent",IF(S8/INDEX($D8:$Q8,MATCH($B$3,$D$4:$Q$4,0)-1)<-0.2,"FREQUENCY LOSS",IF(AND(R8<-0.1,S8>=0),"WIN",IF(R8>0.1,"LOSS",IF(S8/INDEX($D8:$Q8,MATCH($B$3,$D$4:$Q$4,0)-1)>0.2,"FREQUENCY GAIN","hold")))))))),"")
A9: What community colleges in Ohio have flexible or online classes? | B9: ONLINE — flexible | C9: ChatGPT | D9: 2.86 | E9: 24 | F9: 1.57 | G9: 30 | R9: =IFERROR(IF(AND(ISNUMBER(INDEX($D9:$Q9,MATCH($B$3,$D$4:$Q$4,0))),ISNUMBER(INDEX($D9:$Q9,MATCH($B$3,$D$4:$Q$4,0)-2))),INDEX($D9:$Q9,MATCH($B$3,$D$4:$Q$4,0))-INDEX($D9:$Q9,MATCH($B$3,$D$4:$Q$4,0)-2),""),"") | S9: =IFERROR(IF(AND(ISNUMBER(INDEX($D9:$Q9,MATCH($B$3,$D$4:$Q$4,0)+1)),ISNUMBER(INDEX($D9:$Q9,MATCH($B$3,$D$4:$Q$4,0)-1))),INDEX($D9:$Q9,MATCH($B$3,$D$4:$Q$4,0)+1)-INDEX($D9:$Q9,MATCH($B$3,$D$4:$Q$4,0)-1),""),"") | T9: =IFERROR(IF(S9="","",IF(AND(INDEX($D9:$Q9,MATCH($B$3,$D$4:$Q$4,0)+1)=0,INDEX($D9:$Q9,MATCH($B$3,$D$4:$Q$4,0)-1)>0),"WENT TO ZERO",IF(AND(INDEX($D9:$Q9,MATCH($B$3,$D$4:$Q$4,0)-1)=0,INDEX($D9:$Q9,MATCH($B$3,$D$4:$Q$4,0)+1)>0),"NEW ENTRY",IF(INDEX($D9:$Q9,MATCH($B$3,$D$4:$Q$4,0)-1)=0,"absent",IF(S9/INDEX($D9:$Q9,MATCH($B$3,$D$4:$Q$4,0)-1)<-0.2,"FREQUENCY LOSS",IF(AND(R9<-0.1,S9>=0),"WIN",IF(R9>0.1,"LOSS",IF(S9/INDEX($D9:$Q9,MATCH($B$3,$D$4:$Q$4,0)-1)>0.2,"FREQUENCY GAIN","hold")))))))),"")
A10: What community colleges in Ohio have flexible or online classes? | B10: ONLINE — flexible | C10: Gemini | D10: 1.13 | E10: 31 | F10: 1.18 | G10: 31 | R10: =IFERROR(IF(AND(ISNUMBER(INDEX($D10:$Q10,MATCH($B$3,$D$4:$Q$4,0))),ISNUMBER(INDEX($D10:$Q10,MATCH($B$3,$D$4:$Q$4,0)-2))),INDEX($D10:$Q10,MATCH($B$3,$D$4:$Q$4,0))-INDEX($D10:$Q10,MATCH($B$3,$D$4:$Q$4,0)-2),""),"") | S10: =IFERROR(IF(AND(ISNUMBER(INDEX($D10:$Q10,MATCH($B$3,$D$4:$Q$4,0)+1)),ISNUMBER(INDEX($D10:$Q10,MATCH($B$3,$D$4:$Q$4,0)-1))),INDEX($D10:$Q10,MATCH($B$3,$D$4:$Q$4,0)+1)-INDEX($D10:$Q10,MATCH($B$3,$D$4:$Q$4,0)-1),""),"") | T10: =IFERROR(IF(S10="","",IF(AND(INDEX($D10:$Q10,MATCH($B$3,$D$4:$Q$4,0)+1)=0,INDEX($D10:$Q10,MATCH($B$3,$D$4:$Q$4,0)-1)>0),"WENT TO ZERO",IF(AND(INDEX($D10:$Q10,MATCH($B$3,$D$4:$Q$4,0)-1)=0,INDEX($D10:$Q10,MATCH($B$3,$D$4:$Q$4,0)+1)>0),"NEW ENTRY",IF(INDEX($D10:$Q10,MATCH($B$3,$D$4:$Q$4,0)-1)=0,"absent",IF(S10/INDEX($D10:$Q10,MATCH($B$3,$D$4:$Q$4,0)-1)<-0.2,"FREQUENCY LOSS",IF(AND(R10<-0.1,S10>=0),"WIN",IF(R10>0.1,"LOSS",IF(S10/INDEX($D10:$Q10,MATCH($B$3,$D$4:$Q$4,0)-1)>0.2,"FREQUENCY GAIN","hold")))))))),"")
A11: What community colleges in Ohio have flexible or online classes? | B11: ONLINE — flexible | C11: Google AI Overview | D11: 2.45 | E11: 22 | F11: 1.67 | G11: 25 | R11: =IFERROR(IF(AND(ISNUMBER(INDEX($D11:$Q11,MATCH($B$3,$D$4:$Q$4,0))),ISNUMBER(INDEX($D11:$Q11,MATCH($B$3,$D$4:$Q$4,0)-2))),INDEX($D11:$Q11,MATCH($B$3,$D$4:$Q$4,0))-INDEX($D11:$Q11,MATCH($B$3,$D$4:$Q$4,0)-2),""),"") | S11: =IFERROR(IF(AND(ISNUMBER(INDEX($D11:$Q11,MATCH($B$3,$D$4:$Q$4,0)+1)),ISNUMBER(INDEX($D11:$Q11,MATCH($B$3,$D$4:$Q$4,0)-1))),INDEX($D11:$Q11,MATCH($B$3,$D$4:$Q$4,0)+1)-INDEX($D11:$Q11,MATCH($B$3,$D$4:$Q$4,0)-1),""),"") | T11: =IFERROR(IF(S11="","",IF(AND(INDEX($D11:$Q11,MATCH($B$3,$D$4:$Q$4,0)+1)=0,INDEX($D11:$Q11,MATCH($B$3,$D$4:$Q$4,0)-1)>0),"WENT TO ZERO",IF(AND(INDEX($D11:$Q11,MATCH($B$3,$D$4:$Q$4,0)-1)=0,INDEX($D11:$Q11,MATCH($B$3,$D$4:$Q$4,0)+1)>0),"NEW ENTRY",IF(INDEX($D11:$Q11,MATCH($B$3,$D$4:$Q$4,0)-1)=0,"absent",IF(S11/INDEX($D11:$Q11,MATCH($B$3,$D$4:$Q$4,0)-1)<-0.2,"FREQUENCY LOSS",IF(AND(R11<-0.1,S11>=0),"WIN",IF(R11>0.1,"LOSS",IF(S11/INDEX($D11:$Q11,MATCH($B$3,$D$4:$Q$4,0)-1)>0.2,"FREQUENCY GAIN","hold")))))))),"")
A12: What financial aid or scholarships are available for community college students in Ohio? | B12: Financial aid | C12: ChatGPT | D12: 1.09 | E12: 30 | F12: 1.19 | G12: 30 | R12: =IFERROR(IF(AND(ISNUMBER(INDEX($D12:$Q12,MATCH($B$3,$D$4:$Q$4,0))),ISNUMBER(INDEX($D12:$Q12,MATCH($B$3,$D$4:$Q$4,0)-2))),INDEX($D12:$Q12,MATCH($B$3,$D$4:$Q$4,0))-INDEX($D12:$Q12,MATCH($B$3,$D$4:$Q$4,0)-2),""),"") | S12: =IFERROR(IF(AND(ISNUMBER(INDEX($D12:$Q12,MATCH($B$3,$D$4:$Q$4,0)+1)),ISNUMBER(INDEX($D12:$Q12,MATCH($B$3,$D$4:$Q$4,0)-1))),INDEX($D12:$Q12,MATCH($B$3,$D$4:$Q$4,0)+1)-INDEX($D12:$Q12,MATCH($B$3,$D$4:$Q$4,0)-1),""),"") | T12: =IFERROR(IF(S12="","",IF(AND(INDEX($D12:$Q12,MATCH($B$3,$D$4:$Q$4,0)+1)=0,INDEX($D12:$Q12,MATCH($B$3,$D$4:$Q$4,0)-1)>0),"WENT TO ZERO",IF(AND(INDEX($D12:$Q12,MATCH($B$3,$D$4:$Q$4,0)-1)=0,INDEX($D12:$Q12,MATCH($B$3,$D$4:$Q$4,0)+1)>0),"NEW ENTRY",IF(INDEX($D12:$Q12,MATCH($B$3,$D$4:$Q$4,0)-1)=0,"absent",IF(S12/INDEX($D12:$Q12,MATCH($B$3,$D$4:$Q$4,0)-1)<-0.2,"FREQUENCY LOSS",IF(AND(R12<-0.1,S12>=0),"WIN",IF(R12>0.1,"LOSS",IF(S12/INDEX($D12:$Q12,MATCH($B$3,$D$4:$Q$4,0)-1)>0.2,"FREQUENCY GAIN","hold")))))))),"")
A13: What financial aid or scholarships are available for community college students in Ohio? | B13: Financial aid | C13: Gemini | D13: 1 | E13: 31 | F13: 1.12 | G13: 30 | R13: =IFERROR(IF(AND(ISNUMBER(INDEX($D13:$Q13,MATCH($B$3,$D$4:$Q$4,0))),ISNUMBER(INDEX($D13:$Q13,MATCH($B$3,$D$4:$Q$4,0)-2))),INDEX($D13:$Q13,MATCH($B$3,$D$4:$Q$4,0))-INDEX($D13:$Q13,MATCH($B$3,$D$4:$Q$4,0)-2),""),"") | S13: =IFERROR(IF(AND(ISNUMBER(INDEX($D13:$Q13,MATCH($B$3,$D$4:$Q$4,0)+1)),ISNUMBER(INDEX($D13:$Q13,MATCH($B$3,$D$4:$Q$4,0)-1))),INDEX($D13:$Q13,MATCH($B$3,$D$4:$Q$4,0)+1)-INDEX($D13:$Q13,MATCH($B$3,$D$4:$Q$4,0)-1),""),"") | T13: =IFERROR(IF(S13="","",IF(AND(INDEX($D13:$Q13,MATCH($B$3,$D$4:$Q$4,0)+1)=0,INDEX($D13:$Q13,MATCH($B$3,$D$4:$Q$4,0)-1)>0),"WENT TO ZERO",IF(AND(INDEX($D13:$Q13,MATCH($B$3,$D$4:$Q$4,0)-1)=0,INDEX($D13:$Q13,MATCH($B$3,$D$4:$Q$4,0)+1)>0),"NEW ENTRY",IF(INDEX($D13:$Q13,MATCH($B$3,$D$4:$Q$4,0)-1)=0,"absent",IF(S13/INDEX($D13:$Q13,MATCH($B$3,$D$4:$Q$4,0)-1)<-0.2,"FREQUENCY LOSS",IF(AND(R13<-0.1,S13>=0),"WIN",IF(R13>0.1,"LOSS",IF(S13/INDEX($D13:$Q13,MATCH($B$3,$D$4:$Q$4,0)-1)>0.2,"FREQUENCY GAIN","hold")))))))),"")
A14: What financial aid or scholarships are available for community college students in Ohio? | B14: Financial aid | C14: Google AI Overview | D14: 1.99 | E14: 25 | F14: 2.71 | G14: 19 | R14: =IFERROR(IF(AND(ISNUMBER(INDEX($D14:$Q14,MATCH($B$3,$D$4:$Q$4,0))),ISNUMBER(INDEX($D14:$Q14,MATCH($B$3,$D$4:$Q$4,0)-2))),INDEX($D14:$Q14,MATCH($B$3,$D$4:$Q$4,0))-INDEX($D14:$Q14,MATCH($B$3,$D$4:$Q$4,0)-2),""),"") | S14: =IFERROR(IF(AND(ISNUMBER(INDEX($D14:$Q14,MATCH($B$3,$D$4:$Q$4,0)+1)),ISNUMBER(INDEX($D14:$Q14,MATCH($B$3,$D$4:$Q$4,0)-1))),INDEX($D14:$Q14,MATCH($B$3,$D$4:$Q$4,0)+1)-INDEX($D14:$Q14,MATCH($B$3,$D$4:$Q$4,0)-1),""),"") | T14: =IFERROR(IF(S14="","",IF(AND(INDEX($D14:$Q14,MATCH($B$3,$D$4:$Q$4,0)+1)=0,INDEX($D14:$Q14,MATCH($B$3,$D$4:$Q$4,0)-1)>0),"WENT TO ZERO",IF(AND(INDEX($D14:$Q14,MATCH($B$3,$D$4:$Q$4,0)-1)=0,INDEX($D14:$Q14,MATCH($B$3,$D$4:$Q$4,0)+1)>0),"NEW ENTRY",IF(INDEX($D14:$Q14,MATCH($B$3,$D$4:$Q$4,0)-1)=0,"absent",IF(S14/INDEX($D14:$Q14,MATCH($B$3,$D$4:$Q$4,0)-1)<-0.2,"FREQUENCY LOSS",IF(AND(R14<-0.1,S14>=0),"WIN",IF(R14>0.1,"LOSS",IF(S14/INDEX($D14:$Q14,MATCH($B$3,$D$4:$Q$4,0)-1)>0.2,"FREQUENCY GAIN","hold")))))))),"")
A15: best community colleges near me | B15: Location — discovery | C15: ChatGPT | D15: 1 | E15: 31 | F15: 1 | G15: 29 | R15: =IFERROR(IF(AND(ISNUMBER(INDEX($D15:$Q15,MATCH($B$3,$D$4:$Q$4,0))),ISNUMBER(INDEX($D15:$Q15,MATCH($B$3,$D$4:$Q$4,0)-2))),INDEX($D15:$Q15,MATCH($B$3,$D$4:$Q$4,0))-INDEX($D15:$Q15,MATCH($B$3,$D$4:$Q$4,0)-2),""),"") | S15: =IFERROR(IF(AND(ISNUMBER(INDEX($D15:$Q15,MATCH($B$3,$D$4:$Q$4,0)+1)),ISNUMBER(INDEX($D15:$Q15,MATCH($B$3,$D$4:$Q$4,0)-1))),INDEX($D15:$Q15,MATCH($B$3,$D$4:$Q$4,0)+1)-INDEX($D15:$Q15,MATCH($B$3,$D$4:$Q$4,0)-1),""),"") | T15: =IFERROR(IF(S15="","",IF(AND(INDEX($D15:$Q15,MATCH($B$3,$D$4:$Q$4,0)+1)=0,INDEX($D15:$Q15,MATCH($B$3,$D$4:$Q$4,0)-1)>0),"WENT TO ZERO",IF(AND(INDEX($D15:$Q15,MATCH($B$3,$D$4:$Q$4,0)-1)=0,INDEX($D15:$Q15,MATCH($B$3,$D$4:$Q$4,0)+1)>0),"NEW ENTRY",IF(INDEX($D15:$Q15,MATCH($B$3,$D$4:$Q$4,0)-1)=0,"absent",IF(S15/INDEX($D15:$Q15,MATCH($B$3,$D$4:$Q$4,0)-1)<-0.2,"FREQUENCY LOSS",IF(AND(R15<-0.1,S15>=0),"WIN",IF(R15>0.1,"LOSS",IF(S15/INDEX($D15:$Q15,MATCH($B$3,$D$4:$Q$4,0)-1)>0.2,"FREQUENCY GAIN","hold")))))))),"")
A16: best community colleges near me | B16: Location — discovery | C16: Gemini | D16: 1.25 | E16: 30 | F16: 1.23 | G16: 28 | R16: =IFERROR(IF(AND(ISNUMBER(INDEX($D16:$Q16,MATCH($B$3,$D$4:$Q$4,0))),ISNUMBER(INDEX($D16:$Q16,MATCH($B$3,$D$4:$Q$4,0)-2))),INDEX($D16:$Q16,MATCH($B$3,$D$4:$Q$4,0))-INDEX($D16:$Q16,MATCH($B$3,$D$4:$Q$4,0)-2),""),"") | S16: =IFERROR(IF(AND(ISNUMBER(INDEX($D16:$Q16,MATCH($B$3,$D$4:$Q$4,0)+1)),ISNUMBER(INDEX($D16:$Q16,MATCH($B$3,$D$4:$Q$4,0)-1))),INDEX($D16:$Q16,MATCH($B$3,$D$4:$Q$4,0)+1)-INDEX($D16:$Q16,MATCH($B$3,$D$4:$Q$4,0)-1),""),"") | T16: =IFERROR(IF(S16="","",IF(AND(INDEX($D16:$Q16,MATCH($B$3,$D$4:$Q$4,0)+1)=0,INDEX($D16:$Q16,MATCH($B$3,$D$4:$Q$4,0)-1)>0),"WENT TO ZERO",IF(AND(INDEX($D16:$Q16,MATCH($B$3,$D$4:$Q$4,0)-1)=0,INDEX($D16:$Q16,MATCH($B$3,$D$4:$Q$4,0)+1)>0),"NEW ENTRY",IF(INDEX($D16:$Q16,MATCH($B$3,$D$4:$Q$4,0)-1)=0,"absent",IF(S16/INDEX($D16:$Q16,MATCH($B$3,$D$4:$Q$4,0)-1)<-0.2,"FREQUENCY LOSS",IF(AND(R16<-0.1,S16>=0),"WIN",IF(R16>0.1,"LOSS",IF(S16/INDEX($D16:$Q16,MATCH($B$3,$D$4:$Q$4,0)-1)>0.2,"FREQUENCY GAIN","hold")))))))),"")
A17: best community colleges near me | B17: Location — discovery | C17: Google AI Overview | D17: 1.1 | E17: 21 | F17: 1 | G17: 29 | R17: =IFERROR(IF(AND(ISNUMBER(INDEX($D17:$Q17,MATCH($B$3,$D$4:$Q$4,0))),ISNUMBER(INDEX($D17:$Q17,MATCH($B$3,$D$4:$Q$4,0)-2))),INDEX($D17:$Q17,MATCH($B$3,$D$4:$Q$4,0))-INDEX($D17:$Q17,MATCH($B$3,$D$4:$Q$4,0)-2),""),"") | S17: =IFERROR(IF(AND(ISNUMBER(INDEX($D17:$Q17,MATCH($B$3,$D$4:$Q$4,0)+1)),ISNUMBER(INDEX($D17:$Q17,MATCH($B$3,$D$4:$Q$4,0)-1))),INDEX($D17:$Q17,MATCH($B$3,$D$4:$Q$4,0)+1)-INDEX($D17:$Q17,MATCH($B$3,$D$4:$Q$4,0)-1),""),"") | T17: =IFERROR(IF(S17="","",IF(AND(INDEX($D17:$Q17,MATCH($B$3,$D$4:$Q$4,0)+1)=0,INDEX($D17:$Q17,MATCH($B$3,$D$4:$Q$4,0)-1)>0),"WENT TO ZERO",IF(AND(INDEX($D17:$Q17,MATCH($B$3,$D$4:$Q$4,0)-1)=0,INDEX($D17:$Q17,MATCH($B$3,$D$4:$Q$4,0)+1)>0),"NEW ENTRY",IF(INDEX($D17:$Q17,MATCH($B$3,$D$4:$Q$4,0)-1)=0,"absent",IF(S17/INDEX($D17:$Q17,MATCH($B$3,$D$4:$Q$4,0)-1)<-0.2,"FREQUENCY LOSS",IF(AND(R17<-0.1,S17>=0),"WIN",IF(R17>0.1,"LOSS",IF(S17/INDEX($D17:$Q17,MATCH($B$3,$D$4:$Q$4,0)-1)>0.2,"FREQUENCY GAIN","hold")))))))),"")
... A19: cna classes near me | B19: CNA | C19: Gemini | D19: 1 | E19: 31 | F19: 1 | G19: 31 | R19: =IFERROR(IF(AND(ISNUMBER(INDEX($D19:$Q19,MATCH($B$3,$D$4:$Q$4,0))),ISNUMBER(INDEX($D19:$Q19,MATCH($B$3,$D$4:$Q$4,0)-2))),INDEX($D19:$Q19,MATCH($B$3,$D$4:$Q$4,0))-INDEX($D19:$Q19,MATCH($B$3,$D$4:$Q$4,0)-2),""),"") | S19: =IFERROR(IF(AND(ISNUMBER(INDEX($D19:$Q19,MATCH($B$3,$D$4:$Q$4,0)+1)),ISNUMBER(INDEX($D19:$Q19,MATCH($B$3,$D$4:$Q$4,0)-1))),INDEX($D19:$Q19,MATCH($B$3,$D$4:$Q$4,0)+1)-INDEX($D19:$Q19,MATCH($B$3,$D$4:$Q$4,0)-1),""),"") | T19: =IFERROR(IF(S19="","",IF(AND(INDEX($D19:$Q19,MATCH($B$3,$D$4:$Q$4,0)+1)=0,INDEX($D19:$Q19,MATCH($B$3,$D$4:$Q$4,0)-1)>0),"WENT TO ZERO",IF(AND(INDEX($D19:$Q19,MATCH($B$3,$D$4:$Q$4,0)-1)=0,INDEX($D19:$Q19,MATCH($B$3,$D$4:$Q$4,0)+1)>0),"NEW ENTRY",IF(INDEX($D19:$Q19,MATCH($B$3,$D$4:$Q$4,0)-1)=0,"absent",IF(S19/INDEX($D19:$Q19,MATCH($B$3,$D$4:$Q$4,0)-1)<-0.2,"FREQUENCY LOSS",IF(AND(R19<-0.1,S19>=0),"WIN",IF(R19>0.1,"LOSS",IF(S19/INDEX($D19:$Q19,MATCH($B$3,$D$4:$Q$4,0)-1)>0.2,"FREQUENCY GAIN","hold")))))))),"")
A20: cna classes near me | B20: CNA | C20: Google AI Overview | E20: 0 | F20: 1 | G20: 8 | R20: =IFERROR(IF(AND(ISNUMBER(INDEX($D20:$Q20,MATCH($B$3,$D$4:$Q$4,0))),ISNUMBER(INDEX($D20:$Q20,MATCH($B$3,$D$4:$Q$4,0)-2))),INDEX($D20:$Q20,MATCH($B$3,$D$4:$Q$4,0))-INDEX($D20:$Q20,MATCH($B$3,$D$4:$Q$4,0)-2),""),"") | S20: =IFERROR(IF(AND(ISNUMBER(INDEX($D20:$Q20,MATCH($B$3,$D$4:$Q$4,0)+1)),ISNUMBER(INDEX($D20:$Q20,MATCH($B$3,$D$4:$Q$4,0)-1))),INDEX($D20:$Q20,MATCH($B$3,$D$4:$Q$4,0)+1)-INDEX($D20:$Q20,MATCH($B$3,$D$4:$Q$4,0)-1),""),"") | T20: =IFERROR(IF(S20="","",IF(AND(INDEX($D20:$Q20,MATCH($B$3,$D$4:$Q$4,0)+1)=0,INDEX($D20:$Q20,MATCH($B$3,$D$4:$Q$4,0)-1)>0),"WENT TO ZERO",IF(AND(INDEX($D20:$Q20,MATCH($B$3,$D$4:$Q$4,0)-1)=0,INDEX($D20:$Q20,MATCH($B$3,$D$4:$Q$4,0)+1)>0),"NEW ENTRY",IF(INDEX($D20:$Q20,MATCH($B$3,$D$4:$Q$4,0)-1)=0,"absent",IF(S20/INDEX($D20:$Q20,MATCH($B$3,$D$4:$Q$4,0)-1)<-0.2,"FREQUENCY LOSS",IF(AND(R20<-0.1,S20>=0),"WIN",IF(R20>0.1,"LOSS",IF(S20/INDEX($D20:$Q20,MATCH($B$3,$D$4:$Q$4,0)-1)>0.2,"FREQUENCY GAIN","hold")))))))),"")
A21: colleges that have surgical tech programs | B21: Surgical tech | C21: ChatGPT | D21: 1 | E21: 30 | F21: 1 | G21: 31 | R21: =IFERROR(IF(AND(ISNUMBER(INDEX($D21:$Q21,MATCH($B$3,$D$4:$Q$4,0))),ISNUMBER(INDEX($D21:$Q21,MATCH($B$3,$D$4:$Q$4,0)-2))),INDEX($D21:$Q21,MATCH($B$3,$D$4:$Q$4,0))-INDEX($D21:$Q21,MATCH($B$3,$D$4:$Q$4,0)-2),""),"") | S21: =IFERROR(IF(AND(ISNUMBER(INDEX($D21:$Q21,MATCH($B$3,$D$4:$Q$4,0)+1)),ISNUMBER(INDEX($D21:$Q21,MATCH($B$3,$D$4:$Q$4,0)-1))),INDEX($D21:$Q21,MATCH($B$3,$D$4:$Q$4,0)+1)-INDEX($D21:$Q21,MATCH($B$3,$D$4:$Q$4,0)-1),""),"") | T21: =IFERROR(IF(S21="","",IF(AND(INDEX($D21:$Q21,MATCH($B$3,$D$4:$Q$4,0)+1)=0,INDEX($D21:$Q21,MATCH($B$3,$D$4:$Q$4,0)-1)>0),"WENT TO ZERO",IF(AND(INDEX($D21:$Q21,MATCH($B$3,$D$4:$Q$4,0)-1)=0,INDEX($D21:$Q21,MATCH($B$3,$D$4:$Q$4,0)+1)>0),"NEW ENTRY",IF(INDEX($D21:$Q21,MATCH($B$3,$D$4:$Q$4,0)-1)=0,"absent",IF(S21/INDEX($D21:$Q21,MATCH($B$3,$D$4:$Q$4,0)-1)<-0.2,"FREQUENCY LOSS",IF(AND(R21<-0.1,S21>=0),"WIN",IF(R21>0.1,"LOSS",IF(S21/INDEX($D21:$Q21,MATCH($B$3,$D$4:$Q$4,0)-1)>0.2,"FREQUENCY GAIN","hold")))))))),"")
A22: colleges that have surgical tech programs | B22: Surgical tech | C22: Gemini | D22: 1 | E22: 29 | F22: 1 | G22: 31 | R22: =IFERROR(IF(AND(ISNUMBER(INDEX($D22:$Q22,MATCH($B$3,$D$4:$Q$4,0))),ISNUMBER(INDEX($D22:$Q22,MATCH($B$3,$D$4:$Q$4,0)-2))),INDEX($D22:$Q22,MATCH($B$3,$D$4:$Q$4,0))-INDEX($D22:$Q22,MATCH($B$3,$D$4:$Q$4,0)-2),""),"") | S22: =IFERROR(IF(AND(ISNUMBER(INDEX($D22:$Q22,MATCH($B$3,$D$4:$Q$4,0)+1)),ISNUMBER(INDEX($D22:$Q22,MATCH($B$3,$D$4:$Q$4,0)-1))),INDEX($D22:$Q22,MATCH($B$3,$D$4:$Q$4,0)+1)-INDEX($D22:$Q22,MATCH($B$3,$D$4:$Q$4,0)-1),""),"") | T22: =IFERROR(IF(S22="","",IF(AND(INDEX($D22:$Q22,MATCH($B$3,$D$4:$Q$4,0)+1)=0,INDEX($D22:$Q22,MATCH($B$3,$D$4:$Q$4,0)-1)>0),"WENT TO ZERO",IF(AND(INDEX($D22:$Q22,MATCH($B$3,$D$4:$Q$4,0)-1)=0,INDEX($D22:$Q22,MATCH($B$3,$D$4:$Q$4,0)+1)>0),"NEW ENTRY",IF(INDEX($D22:$Q22,MATCH($B$3,$D$4:$Q$4,0)-1)=0,"absent",IF(S22/INDEX($D22:$Q22,MATCH($B$3,$D$4:$Q$4,0)-1)<-0.2,"FREQUENCY LOSS",IF(AND(R22<-0.1,S22>=0),"WIN",IF(R22>0.1,"LOSS",IF(S22/INDEX($D22:$Q22,MATCH($B$3,$D$4:$Q$4,0)-1)>0.2,"FREQUENCY GAIN","hold")))))))),"")
A23: colleges that have surgical tech programs | B23: Surgical tech | C23: Google AI Overview | D23: 1.27 | E23: 31 | F23: 1 | G23: 28 | R23: =IFERROR(IF(AND(ISNUMBER(INDEX($D23:$Q23,MATCH($B$3,$D$4:$Q$4,0))),ISNUMBER(INDEX($D23:$Q23,MATCH($B$3,$D$4:$Q$4,0)-2))),INDEX($D23:$Q23,MATCH($B$3,$D$4:$Q$4,0))-INDEX($D23:$Q23,MATCH($B$3,$D$4:$Q$4,0)-2),""),"") | S23: =IFERROR(IF(AND(ISNUMBER(INDEX($D23:$Q23,MATCH($B$3,$D$4:$Q$4,0)+1)),ISNUMBER(INDEX($D23:$Q23,MATCH($B$3,$D$4:$Q$4,0)-1))),INDEX($D23:$Q23,MATCH($B$3,$D$4:$Q$4,0)+1)-INDEX($D23:$Q23,MATCH($B$3,$D$4:$Q$4,0)-1),""),"") | T23: =IFERROR(IF(S23="","",IF(AND(INDEX($D23:$Q23,MATCH($B$3,$D$4:$Q$4,0)+1)=0,INDEX($D23:$Q23,MATCH($B$3,$D$4:$Q$4,0)-1)>0),"WENT TO ZERO",IF(AND(INDEX($D23:$Q23,MATCH($B$3,$D$4:$Q$4,0)-1)=0,INDEX($D23:$Q23,MATCH($B$3,$D$4:$Q$4,0)+1)>0),"NEW ENTRY",IF(INDEX($D23:$Q23,MATCH($B$3,$D$4:$Q$4,0)-1)=0,"absent",IF(S23/INDEX($D23:$Q23,MATCH($B$3,$D$4:$Q$4,0)-1)<-0.2,"FREQUENCY LOSS",IF(AND(R23<-0.1,S23>=0),"WIN",IF(R23>0.1,"LOSS",IF(S23/INDEX($D23:$Q23,MATCH($B$3,$D$4:$Q$4,0)-1)>0.2,"FREQUENCY GAIN","hold")))))))),"")
A24: community colleges in ohio | B24: Location — state | C24: ChatGPT | D24: 2.95 | E24: 31 | F24: 2.03 | G24: 30 | R24: =IFERROR(IF(AND(ISNUMBER(INDEX($D24:$Q24,MATCH($B$3,$D$4:$Q$4,0))),ISNUMBER(INDEX($D24:$Q24,MATCH($B$3,$D$4:$Q$4,0)-2))),INDEX($D24:$Q24,MATCH($B$3,$D$4:$Q$4,0))-INDEX($D24:$Q24,MATCH($B$3,$D$4:$Q$4,0)-2),""),"") | S24: =IFERROR(IF(AND(ISNUMBER(INDEX($D24:$Q24,MATCH($B$3,$D$4:$Q$4,0)+1)),ISNUMBER(INDEX($D24:$Q24,MATCH($B$3,$D$4:$Q$4,0)-1))),INDEX($D24:$Q24,MATCH($B$3,$D$4:$Q$4,0)+1)-INDEX($D24:$Q24,MATCH($B$3,$D$4:$Q$4,0)-1),""),"") | T24: =IFERROR(IF(S24="","",IF(AND(INDEX($D24:$Q24,MATCH($B$3,$D$4:$Q$4,0)+1)=0,INDEX($D24:$Q24,MATCH($B$3,$D$4:$Q$4,0)-1)>0),"WENT TO ZERO",IF(AND(INDEX($D24:$Q24,MATCH($B$3,$D$4:$Q$4,0)-1)=0,INDEX($D24:$Q24,MATCH($B$3,$D$4:$Q$4,0)+1)>0),"NEW ENTRY",IF(INDEX($D24:$Q24,MATCH($B$3,$D$4:$Q$4,0)-1)=0,"absent",IF(S24/INDEX($D24:$Q24,MATCH($B$3,$D$4:$Q$4,0)-1)<-0.2,"FREQUENCY LOSS",IF(AND(R24<-0.1,S24>=0),"WIN",IF(R24>0.1,"LOSS",IF(S24/INDEX($D24:$Q24,MATCH($B$3,$D$4:$Q$4,0)-1)>0.2,"FREQUENCY GAIN","hold")))))))),"")
A25: community colleges in ohio | B25: Location — state | C25: Gemini | D25: 1.28 | E25: 30 | F25: 1.21 | G25: 27 | R25: =IFERROR(IF(AND(ISNUMBER(INDEX($D25:$Q25,MATCH($B$3,$D$4:$Q$4,0))),ISNUMBER(INDEX($D25:$Q25,MATCH($B$3,$D$4:$Q$4,0)-2))),INDEX($D25:$Q25,MATCH($B$3,$D$4:$Q$4,0))-INDEX($D25:$Q25,MATCH($B$3,$D$4:$Q$4,0)-2),""),"") | S25: =IFERROR(IF(AND(ISNUMBER(INDEX($D25:$Q25,MATCH($B$3,$D$4:$Q$4,0)+1)),ISNUMBER(INDEX($D25:$Q25,MATCH($B$3,$D$4:$Q$4,0)-1))),INDEX($D25:$Q25,MATCH($B$3,$D$4:$Q$4,0)+1)-INDEX($D25:$Q25,MATCH($B$3,$D$4:$Q$4,0)-1),""),"") | T25: =IFERROR(IF(S25="","",IF(AND(INDEX($D25:$Q25,MATCH($B$3,$D$4:$Q$4,0)+1)=0,INDEX($D25:$Q25,MATCH($B$3,$D$4:$Q$4,0)-1)>0),"WENT TO ZERO",IF(AND(INDEX($D25:$Q25,MATCH($B$3,$D$4:$Q$4,0)-1)=0,INDEX($D25:$Q25,MATCH($B$3,$D$4:$Q$4,0)+1)>0),"NEW ENTRY",IF(INDEX($D25:$Q25,MATCH($B$3,$D$4:$Q$4,0)-1)=0,"absent",IF(S25/INDEX($D25:$Q25,MATCH($B$3,$D$4:$Q$4,0)-1)<-0.2,"FREQUENCY LOSS",IF(AND(R25<-0.1,S25>=0),"WIN",IF(R25>0.1,"LOSS",IF(S25/INDEX($D25:$Q25,MATCH($B$3,$D$4:$Q$4,0)-1)>0.2,"FREQUENCY GAIN","hold")))))))),"")
A26: community colleges in ohio | B26: Location — state | C26: Google AI Overview | D26: 5.02 | E26: 3 | G26: 0 | R26: =IFERROR(IF(AND(ISNUMBER(INDEX($D26:$Q26,MATCH($B$3,$D$4:$Q$4,0))),ISNUMBER(INDEX($D26:$Q26,MATCH($B$3,$D$4:$Q$4,0)-2))),INDEX($D26:$Q26,MATCH($B$3,$D$4:$Q$4,0))-INDEX($D26:$Q26,MATCH($B$3,$D$4:$Q$4,0)-2),""),"") | S26: =IFERROR(IF(AND(ISNUMBER(INDEX($D26:$Q26,MATCH($B$3,$D$4:$Q$4,0)+1)),ISNUMBER(INDEX($D26:$Q26,MATCH($B$3,$D$4:$Q$4,0)-1))),INDEX($D26:$Q26,MATCH($B$3,$D$4:$Q$4,0)+1)-INDEX($D26:$Q26,MATCH($B$3,$D$4:$Q$4,0)-1),""),"") | T26: =IFERROR(IF(S26="","",IF(AND(INDEX($D26:$Q26,MATCH($B$3,$D$4:$Q$4,0)+1)=0,INDEX($D26:$Q26,MATCH($B$3,$D$4:$Q$4,0)-1)>0),"WENT TO ZERO",IF(AND(INDEX($D26:$Q26,MATCH($B$3,$D$4:$Q$4,0)-1)=0,INDEX($D26:$Q26,MATCH($B$3,$D$4:$Q$4,0)+1)>0),"NEW ENTRY",IF(INDEX($D26:$Q26,MATCH($B$3,$D$4:$Q$4,0)-1)=0,"absent",IF(S26/INDEX($D26:$Q26,MATCH($B$3,$D$4:$Q$4,0)-1)<-0.2,"FREQUENCY LOSS",IF(AND(R26<-0.1,S26>=0),"WIN",IF(R26>0.1,"LOSS",IF(S26/INDEX($D26:$Q26,MATCH($B$3,$D$4:$Q$4,0)-1)>0.2,"FREQUENCY GAIN","hold")))))))),"")
A27: community colleges in cedar valley | B27: Location — city | C27: ChatGPT | D27: 1 | E27: 31 | F27: 1 | G27: 31 | R27: =IFERROR(IF(AND(ISNUMBER(INDEX($D27:$Q27,MATCH($B$3,$D$4:$Q$4,0))),ISNUMBER(INDEX($D27:$Q27,MATCH($B$3,$D$4:$Q$4,0)-2))),INDEX($D27:$Q27,MATCH($B$3,$D$4:$Q$4,0))-INDEX($D27:$Q27,MATCH($B$3,$D$4:$Q$4,0)-2),""),"") | S27: =IFERROR(IF(AND(ISNUMBER(INDEX($D27:$Q27,MATCH($B$3,$D$4:$Q$4,0)+1)),ISNUMBER(INDEX($D27:$Q27,MATCH($B$3,$D$4:$Q$4,0)-1))),INDEX($D27:$Q27,MATCH($B$3,$D$4:$Q$4,0)+1)-INDEX($D27:$Q27,MATCH($B$3,$D$4:$Q$4,0)-1),""),"") | T27: =IFERROR(IF(S27="","",IF(AND(INDEX($D27:$Q27,MATCH($B$3,$D$4:$Q$4,0)+1)=0,INDEX($D27:$Q27,MATCH($B$3,$D$4:$Q$4,0)-1)>0),"WENT TO ZERO",IF(AND(INDEX($D27:$Q27,MATCH($B$3,$D$4:$Q$4,0)-1)=0,INDEX($D27:$Q27,MATCH($B$3,$D$4:$Q$4,0)+1)>0),"NEW ENTRY",IF(INDEX($D27:$Q27,MATCH($B$3,$D$4:$Q$4,0)-1)=0,"absent",IF(S27/INDEX($D27:$Q27,MATCH($B$3,$D$4:$Q$4,0)-1)<-0.2,"FREQUENCY LOSS",IF(AND(R27<-0.1,S27>=0),"WIN",IF(R27>0.1,"LOSS",IF(S27/INDEX($D27:$Q27,MATCH($B$3,$D$4:$Q$4,0)-1)>0.2,"FREQUENCY GAIN","hold")))))))),"")
A28: community colleges in cedar valley | B28: Location — city | C28: Gemini | D28: 1 | E28: 29 | F28: 1 | G28: 31 | R28: =IFERROR(IF(AND(ISNUMBER(INDEX($D28:$Q28,MATCH($B$3,$D$4:$Q$4,0))),ISNUMBER(INDEX($D28:$Q28,MATCH($B$3,$D$4:$Q$4,0)-2))),INDEX($D28:$Q28,MATCH($B$3,$D$4:$Q$4,0))-INDEX($D28:$Q28,MATCH($B$3,$D$4:$Q$4,0)-2),""),"") | S28: =IFERROR(IF(AND(ISNUMBER(INDEX($D28:$Q28,MATCH($B$3,$D$4:$Q$4,0)+1)),ISNUMBER(INDEX($D28:$Q28,MATCH($B$3,$D$4:$Q$4,0)-1))),INDEX($D28:$Q28,MATCH($B$3,$D$4:$Q$4,0)+1)-INDEX($D28:$Q28,MATCH($B$3,$D$4:$Q$4,0)-1),""),"") | T28: =IFERROR(IF(S28="","",IF(AND(INDEX($D28:$Q28,MATCH($B$3,$D$4:$Q$4,0)+1)=0,INDEX($D28:$Q28,MATCH($B$3,$D$4:$Q$4,0)-1)>0),"WENT TO ZERO",IF(AND(INDEX($D28:$Q28,MATCH($B$3,$D$4:$Q$4,0)-1)=0,INDEX($D28:$Q28,MATCH($B$3,$D$4:$Q$4,0)+1)>0),"NEW ENTRY",IF(INDEX($D28:$Q28,MATCH($B$3,$D$4:$Q$4,0)-1)=0,"absent",IF(S28/INDEX($D28:$Q28,MATCH($B$3,$D$4:$Q$4,0)-1)<-0.2,"FREQUENCY LOSS",IF(AND(R28<-0.1,S28>=0),"WIN",IF(R28>0.1,"LOSS",IF(S28/INDEX($D28:$Q28,MATCH($B$3,$D$4:$Q$4,0)-1)>0.2,"FREQUENCY GAIN","hold")))))))),"")
A29: community colleges in cedar valley | B29: Location — city | C29: Google AI Overview | D29: 1 | E29: 1 | R29: =IFERROR(IF(AND(ISNUMBER(INDEX($D29:$Q29,MATCH($B$3,$D$4:$Q$4,0))),ISNUMBER(INDEX($D29:$Q29,MATCH($B$3,$D$4:$Q$4,0)-2))),INDEX($D29:$Q29,MATCH($B$3,$D$4:$Q$4,0))-INDEX($D29:$Q29,MATCH($B$3,$D$4:$Q$4,0)-2),""),"") | S29: =IFERROR(IF(AND(ISNUMBER(INDEX($D29:$Q29,MATCH($B$3,$D$4:$Q$4,0)+1)),ISNUMBER(INDEX($D29:$Q29,MATCH($B$3,$D$4:$Q$4,0)-1))),INDEX($D29:$Q29,MATCH($B$3,$D$4:$Q$4,0)+1)-INDEX($D29:$Q29,MATCH($B$3,$D$4:$Q$4,0)-1),""),"") | T29: =IFERROR(IF(S29="","",IF(AND(INDEX($D29:$Q29,MATCH($B$3,$D$4:$Q$4,0)+1)=0,INDEX($D29:$Q29,MATCH($B$3,$D$4:$Q$4,0)-1)>0),"WENT TO ZERO",IF(AND(INDEX($D29:$Q29,MATCH($B$3,$D$4:$Q$4,0)-1)=0,INDEX($D29:$Q29,MATCH($B$3,$D$4:$Q$4,0)+1)>0),"NEW ENTRY",IF(INDEX($D29:$Q29,MATCH($B$3,$D$4:$Q$4,0)-1)=0,"absent",IF(S29/INDEX($D29:$Q29,MATCH($B$3,$D$4:$Q$4,0)-1)<-0.2,"FREQUENCY LOSS",IF(AND(R29<-0.1,S29>=0),"WIN",IF(R29>0.1,"LOSS",IF(S29/INDEX($D29:$Q29,MATCH($B$3,$D$4:$Q$4,0)-1)>0.2,"FREQUENCY GAIN","hold")))))))),"")
A30: community colleges that offer surgical technology | B30: Surgical tech | C30: ChatGPT | D30: 1.06 | E30: 31 | F30: 1.05 | G30: 31 | R30: =IFERROR(IF(AND(ISNUMBER(INDEX($D30:$Q30,MATCH($B$3,$D$4:$Q$4,0))),ISNUMBER(INDEX($D30:$Q30,MATCH($B$3,$D$4:$Q$4,0)-2))),INDEX($D30:$Q30,MATCH($B$3,$D$4:$Q$4,0))-INDEX($D30:$Q30,MATCH($B$3,$D$4:$Q$4,0)-2),""),"") | S30: =IFERROR(IF(AND(ISNUMBER(INDEX($D30:$Q30,MATCH($B$3,$D$4:$Q$4,0)+1)),ISNUMBER(INDEX($D30:$Q30,MATCH($B$3,$D$4:$Q$4,0)-1))),INDEX($D30:$Q30,MATCH($B$3,$D$4:$Q$4,0)+1)-INDEX($D30:$Q30,MATCH($B$3,$D$4:$Q$4,0)-1),""),"") | T30: =IFERROR(IF(S30="","",IF(AND(INDEX($D30:$Q30,MATCH($B$3,$D$4:$Q$4,0)+1)=0,INDEX($D30:$Q30,MATCH($B$3,$D$4:$Q$4,0)-1)>0),"WENT TO ZERO",IF(AND(INDEX($D30:$Q30,MATCH($B$3,$D$4:$Q$4,0)-1)=0,INDEX($D30:$Q30,MATCH($B$3,$D$4:$Q$4,0)+1)>0),"NEW ENTRY",IF(INDEX($D30:$Q30,MATCH($B$3,$D$4:$Q$4,0)-1)=0,"absent",IF(S30/INDEX($D30:$Q30,MATCH($B$3,$D$4:$Q$4,0)-1)<-0.2,"FREQUENCY LOSS",IF(AND(R30<-0.1,S30>=0),"WIN",IF(R30>0.1,"LOSS",IF(S30/INDEX($D30:$Q30,MATCH($B$3,$D$4:$Q$4,0)-1)>0.2,"FREQUENCY GAIN","hold")))))))),"")
A31: community colleges that offer surgical technology | B31: Surgical tech | C31: Gemini | D31: 1 | E31: 31 | F31: 1 | G31: 30 | R31: =IFERROR(IF(AND(ISNUMBER(INDEX($D31:$Q31,MATCH($B$3,$D$4:$Q$4,0))),ISNUMBER(INDEX($D31:$Q31,MATCH($B$3,$D$4:$Q$4,0)-2))),INDEX($D31:$Q31,MATCH($B$3,$D$4:$Q$4,0))-INDEX($D31:$Q31,MATCH($B$3,$D$4:$Q$4,0)-2),""),"") | S31: =IFERROR(IF(AND(ISNUMBER(INDEX($D31:$Q31,MATCH($B$3,$D$4:$Q$4,0)+1)),ISNUMBER(INDEX($D31:$Q31,MATCH($B$3,$D$4:$Q$4,0)-1))),INDEX($D31:$Q31,MATCH($B$3,$D$4:$Q$4,0)+1)-INDEX($D31:$Q31,MATCH($B$3,$D$4:$Q$4,0)-1),""),"") | T31: =IFERROR(IF(S31="","",IF(AND(INDEX($D31:$Q31,MATCH($B$3,$D$4:$Q$4,0)+1)=0,INDEX($D31:$Q31,MATCH($B$3,$D$4:$Q$4,0)-1)>0),"WENT TO ZERO",IF(AND(INDEX($D31:$Q31,MATCH($B$3,$D$4:$Q$4,0)-1)=0,INDEX($D31:$Q31,MATCH($B$3,$D$4:$Q$4,0)+1)>0),"NEW ENTRY",IF(INDEX($D31:$Q31,MATCH($B$3,$D$4:$Q$4,0)-1)=0,"absent",IF(S31/INDEX($D31:$Q31,MATCH($B$3,$D$4:$Q$4,0)-1)<-0.2,"FREQUENCY LOSS",IF(AND(R31<-0.1,S31>=0),"WIN",IF(R31>0.1,"LOSS",IF(S31/INDEX($D31:$Q31,MATCH($B$3,$D$4:$Q$4,0)-1)>0.2,"FREQUENCY GAIN","hold")))))))),"")
